Workbook
Name AssuranceTable: 'Assurance data'!$A:$D

Sheet Exercise 1
A1: Customer | B1: ST | C1: GENDER | D1: Education | E1: Customer Lifetime Value | F1: Income | G1: Monthly Premium Auto | H1: Number of Open Complaints | I1: Policy Type | J1: Vehicle Class | K1: Total Claim Amount | L1: Date | M1: ST NUEVA | N1: GENDER NUEVA | O1: EDUCATION NUEVO
A2: RB50392 | B2: Washington | C2: NA | D2: Master | F2: 0 | G2: 1000 | H2: 0 | I2: Personal Auto | J2: Four-Door Car | K2: 2.704934 | L2: 35002.705 | M2: Washington | N2: NA | O2: Master
A3: QZ44356 | B3: Arizona | C3: F | D3: Bachelor | E3: 697953.59 | F3: 0 | G3: 94 | H3: 0 | I3: Personal Auto | J3: Four-Door Car | K3: 1131.4649 | L3: 36131.465 | M3: Arizona | N3: F | O3: Bachelor
A4: AI49188 | B4: Nevada | C4: F | D4: Bachelor | E4: 1288743.2 | F4: 48767 | G4: 108 | H4: 0 | I4: Personal Auto | J4: Two-Door Car | K4: 566.47225 | L4: 35566.472 | M4: Nevada | N4: F | O4: Bachelor
A5: WW63253 | B5: California | C5: M | D5: Bachelor | E5: 764586.18 | F5: 0 | G5: 106 | H5: 0 | I5: Corporate Auto | J5: SUV | K5: 529.88134 | L5: 35529.881 | M5: California | N5: M | O5: Bachelor
A6: GA49547 | B6: Washington | C6: M | D6: High School or Below | E6: 536307.65 | F6: 36357 | G6: 68 | H6: 0 | I6: Personal Auto | J6: Four-Door Car | K6: 17.269323 | L6: 35017.269 | M6: Washington | N6: M | O6: High School or Below
A7: OC83172 | B7: Oregon | C7: F | D7: Bachelor | E7: 825629.78 | F7: 62902 | G7: 69 | H7: 0 | I7: Personal Auto | J7: Two-Door Car | K7: 159.38304 | L7: 35159.383 | M7: Oregon | N7: F | O7: Bachelor
A8: XZ87318 | B8: Oregon | C8: F | D8: College | E8: 538089.86 | F8: 55350 | G8: 67 | H8: 0 | I8: Corporate Auto | J8: Four-Door Car | K8: 321.6 | L8: 35321.6 | M8: Oregon | N8: F | O8: College
A9: CF85061 | B9: Arizona | C9: M | D9: Master | E9: 721610.03 | F9: 0 | G9: 101 | H9: 0 | I9: Corporate Auto | J9: Four-Door Car | K9: 363.02968 | L9: 35363.03 | M9: Arizona | N9: M | O9: Master
A10: DY87989 | B10: Oregon | C10: M | D10: Bachelor | E10: 2412750.4 | F10: 14072 | G10: 71 | H10: 0 | I10: Corporate Auto | J10: Four-Door Car | K10: 511.2 | L10: 35511.2 | M10: Oregon | N10: M | O10: Bachelor
A11: BQ94931 | B11: Oregon | C11: F | D11: College | E11: 738817.81 | F11: 28812 | G11: 93 | H11: 0 | I11: Special Auto | J11: Four-Door Car | K11: 425.52783 | L11: 35425.528 | M11: Oregon | N11: F | O11: College
A12: SX51350 | B12: California | C12: M | D12: College | E12: 473899.2 | F12: 0 | G12: 67 | H12: 0 | I12: Personal Auto | J12: Four-Door Car | K12: 482.4 | L12: 35482.4 | M12: California | N12: M | O12: College
A13: VQ65197 | B13: California | C13: NA | D13: College | E13: 819719.71 | F13: 0 | G13: 110 | H13: 0 | I13: Personal Auto | J13: SUV | K13: 528 | L13: 35528 | M13: California | N13: NA | O13: College
A14: DP39365 | B14: California | C14: NA | D14: Master | E14: 879879.7 | F14: 77026 | G14: 110 | H14: 36557 | I14: Corporate Auto | J14: Four-Door Car | K14: 472.02974 | L14: 35472.03 | M14: California | N14: NA | O14: Master
... A79: XW13033 | B79: Nevada | C79: NA | D79: College | E79: 800947.28 | F79: 20961 | G79: 67 | H79: 0 | I79: Personal Auto | J79: Four-Door Car | K79: 321.6 | L79: 35321.6 | M79: Nevada | N79: NA | O79: College
A80: SP81997 | B80: Washington | C80: F | D80: Master | F80: 41275 | G80: 96 | H80: 0 | I80: Personal Auto | J80: Four-Door Car | K80: 41.122303 | L80: 35041.122 | M80: Washington | N80: F | O80: Master
A81: OM82309 | B81: California | C81: NA | D81: Bachelor | E81: 5816655.3 | F81: 61321 | G81: 186 | H81: 36526 | I81: Personal Auto | J81: Luxury Car | K81: 427.63121 | L81: 35427.631 | M81: California | N81: NA | O81: Bachelor
A82: ZU35962 | B82: California | C82: NA | D82: College | E82: 802522.94 | F82: 0 | G82: 77 | H82: 0 | I82: Personal Auto | J82: Two-Door Car | K82: 25.807685 | L82: 35025.808 | M82: California | N82: NA | O82: College
A83: VH85817 | B83: California | C83: NA | D83: High School or Below | E83: 578018.22 | F83: 51066 | G83: 74 | H83: 0 | I83: Personal Auto | J83: Four-Door Car | K83: 787.99331 | L83: 35787.993 | M83: California | N83: NA | O83: High School or Below
A84: DT85712 | B84: California | C84: NA | D84: Doctor | E84: 411853.91 | F84: 34378 | G84: 102 | H84: 0 | I84: Personal Auto | J84: SUV | K84: 489.6 | L84: 35489.6 | M84: California | N84: NA | O84: Doctor
A85: YJ88573 | B85: Nevada | C85: NA | D85: Master | E85: 252307.02 | F85: 43072 | G85: 63 | H85: 0 | I85: Personal Auto | J85: Four-Door Car | K85: 302.4 | L85: 35302.4 | M85: Nevada | N85: NA | O85: Master
A86: SQ19467 | B86: Oregon | C86: NA | D86: College | E86: 655421.64 | F86: 25222 | G86: 90 | H86: 0 | I86: Personal Auto | J86: Four-Door Car | K86: 475.62325 | L86: 35475.623 | M86: Oregon | N86: NA | O86: College
A87: YB66933 | B87: Washington | C87: F | D87: Bachelor | E87: 538275.2 | F87: 77552 | G87: 68 | H87: 36526 | I87: Corporate Auto | J87: Four-Door Car | K87: 45.215059 | L87: 35045.215 | M87: Washington | N87: F | O87: Bachelor
A88: ET79815 | B88: California | C88: NA | D88: College | E88: 592672.94 | F88: 23091 | G88: 96 | H88: 36647 | I88: Personal Auto | J88: Four-Door Car | K88: 460.8 | L88: 35460.8 | M88: California | N88: NA | O88: College
A89: QC35222 | B89: California | C89: NA | D89: Bachelor | E89: 268347.07 | F89: 48269 | G89: 69 | H89: 36586 | I89: Corporate Auto | J89: Four-Door Car | K89: 282.15121 | L89: 35282.151 | M89: California | N89: NA | O89: Bachelor
A90: CJ15590 | B90: Oregon | C90: NA | D90: Bachelor | E90: 269518.24 | F90: 32720 | G90: 67 | H90: 0 | I90: Personal Auto | J90: Four-Door Car | K90: 321.6 | L90: 35321.6 | M90: Oregon | N90: NA | O90: Bachelor
A91: OI48267 | B91: California | C91: NA | D91: College | E91: 604702.52 | F91: 20396 | G91: 76 | H91: 36526 | I91: Personal Auto | J91: Four-Door Car | K91: 364.8 | L91: 35364.8 | M91: California | N91: NA | O91: College
A92: JY67916 | B92: Oregon | C92: NA | D92: College | E92: 1317101.3 | F92: 21513 | G92: 119 | H92: 36526 | I92: Personal Auto | J92: Two-Door Car | K92: 679.82759 | L92: 35679.828 | M92: Oregon | N92: NA | O92: College
... A989: MB90871 | B989: Oregon | C989: F | D989: College | E989: 584741.52 | F989: 23496 | G989: 77 | H989: 0 | I989: Special Auto | J989: Four-Door Car | K989: 13.164097 | L989: 35013.164 | M989: Oregon | N989: F | O989: College
A990: GT62080 | B990: Washington | C990: M | D990: High School or Below | F990: 55561 | G990: 63 | H990: 0 | I990: Personal Auto | J990: Four-Door Car | K990: 227.87207 | L990: 35227.872 | M990: Washington | N990: M | O990: High School or Below
A991: QL77686 | B991: Nevada | C991: F | D991: College | E991: 472478.61 | F991: 23986 | G991: 119 | H991: 0 | I991: Corporate Auto | J991: SUV | K991: 463.33506 | L991: 35463.335 | M991: Nevada | N991: F | O991: College
A992: ON77827 | B992: Arizona | C992: F | D992: Master | E992: 279022.8 | F992: 22974 | G992: 71 | H992: 0 | I992: Personal Auto | J992: Four-Door Car | K992: 180.66797 | L992: 35180.668 | M992: Arizona | N992: F | O992: Master
A993: KP18988 | B993: Oregon | C993: F | D993: High School or Below | E993: 2153133.3 | F993: 0 | G993: 101 | H993: 0 | I993: Personal Auto | J993: Four-Door Car | K993: 484.8 | L993: 35484.8 | M993: Oregon | N993: F | O993: High School or Below
A994: TI92884 | B994: Arizona | C994: M | D994: Bachelor | E994: 1262283.3 | F994: 61844 | G994: 106 | H994: 0 | I994: Personal Auto | J994: Sports Car | K994: 508.8 | L994: 35508.8 | M994: Arizona | N994: M | O994: Bachelor
A995: JH73503 | B995: Arizona | C995: M | D995: Doctor | E995: 2017196.1 | F995: 24804 | G995: 73 | H995: 0 | I995: Personal Auto | J995: Two-Door Car | K995: 350.4 | L995: 35350.4 | M995: Arizona | N995: M | O995: Doctor
A996: YE97964 | B996: California | C996: F | D996: Bachelor | E996: 1646436.6 | F996: 27760 | G996: 104 | H996: 0 | I996: Personal Auto | J996: SUV | K996: 302.76428 | L996: 35302.764 | M996: California | N996: F | O996: Bachelor
A997: VA30351 | B997: Oregon | C997: F | D997: High School or Below | E997: 559538.99 | F997: 74454 | G997: 71 | H997: 0 | I997: Personal Auto | J997: Four-Door Car | K997: 340.8 | L997: 35340.8 | M997: Oregon | N997: F | O997: High School or Below
A998: PV55726 | B998: Oregon | C998: F | D998: Master | E998: 417068.73 | F998: 29462 | G998: 107 | H998: 36526 | I998: Personal Auto | J998: SUV | K998: 513.6 | L998: 35513.6 | M998: Oregon | N998: F | O998: Master
A999: UC88305 | B999: Arizona | C999: F | D999: College | E999: 266544.71 | F999: 52266 | G999: 68 | H999: 0 | I999: Corporate Auto | J999: Two-Door Car | K999: 141.92284 | L999: 35141.923 | M999: Arizona | N999: F | O999: College
A1000: TS53809 | B1000: Oregon | C1000: M | D1000: Bachelor | E1000: 709891.41 | F1000: 0 | G1000: 70 | H1000: 0 | I1000: Personal Auto | J1000: Two-Door Car | K1000: 349.78305 | L1000: 35349.783 | M1000: Oregon | N1000: M | O1000: Bachelor
...

Sheet Exercise 2
A1: Customer | B1: ST | C1: GENDER | D1: Education | E1: Customer Lifetime Value | F1: Income | G1: Monthly Premium Auto | H1: Number of Open Complaints | I1: Policy Type | J1: Vehicle Class | K1: Total Claim Amount | L1: Date | M1: CFV Corregido | N1: TCA
A2: RB50392 | B2: Washington | C2: NA | D2: Master | F2: 0 | G2: 1000 | H2: 0 | I2: Personal Auto | J2: Four-Door Car | K2: 2.704934 | L2: 35002.705 | M2: ='Exercise 1'!E2 -> 0 | N2: ='Exercise 1'!K2 -> 2.704934
A3: QZ44356 | B3: Arizona | C3: F | D3: Bachelor | E3: 697953.59 | F3: 0 | G3: 94 | H3: 0 | I3: Personal Auto | J3: Four-Door Car | K3: 1131.4649 | L3: 36131.465 | M3: ='Exercise 1'!E3 -> 697953.59 | N3: ='Exercise 1'!K3 -> 1131.4649
A4: AI49188 | B4: Nevada | C4: F | D4: Bachelor | E4: 1288743.2 | F4: 48767 | G4: 108 | H4: 0 | I4: Personal Auto | J4: Two-Door Car | K4: 566.47225 | L4: 35566.472 | M4: ='Exercise 1'!E4 -> 1288743.2 | N4: ='Exercise 1'!K4 -> 566.47225
A5: WW63253 | B5: California | C5: M | D5: Bachelor | E5: 764586.18 | F5: 0 | G5: 106 | H5: 0 | I5: Corporate Auto | J5: SUV | K5: 529.88134 | L5: 35529.881 | M5: ='Exercise 1'!E5 -> 764586.18 | N5: ='Exercise 1'!K5 -> 529.88134
A6: GA49547 | B6: Washington | C6: M | D6: High School or Below | E6: 536307.65 | F6: 36357 | G6: 68 | H6: 0 | I6: Personal Auto | J6: Four-Door Car | K6: 17.269323 | L6: 35017.269 | M6: ='Exercise 1'!E6 -> 536307.65 | N6: ='Exercise 1'!K6 -> 17.269323
A7: OC83172 | B7: Oregon | C7: F | D7: Bachelor | E7: 825629.78 | F7: 62902 | G7: 69 | H7: 0 | I7: Personal Auto | J7: Two-Door Car | K7: 159.38304 | L7: 35159.383 | M7: ='Exercise 1'!E7 -> 825629.78 | N7: ='Exercise 1'!K7 -> 159.38304
A8: XZ87318 | B8: Oregon | C8: F | D8: College | E8: 538089.86 | F8: 55350 | G8: 67 | H8: 0 | I8: Corporate Auto | J8: Four-Door Car | K8: 321.6 | L8: 35321.6 | M8: ='Exercise 1'!E8 -> 538089.86 | N8: ='Exercise 1'!K8 -> 321.6
A9: CF85061 | B9: Arizona | C9: M | D9: Master | E9: 721610.03 | F9: 0 | G9: 101 | H9: 0 | I9: Corporate Auto | J9: Four-Door Car | K9: 363.02968 | L9: 35363.03 | M9: ='Exercise 1'!E9 -> 721610.03 | N9: ='Exercise 1'!K9 -> 363.02968
A10: DY87989 | B10: Oregon | C10: M | D10: Bachelor | E10: 2412750.4 | F10: 14072 | G10: 71 | H10: 0 | I10: Corporate Auto | J10: Four-Door Car | K10: 511.2 | L10: 35511.2 | M10: ='Exercise 1'!E10 -> 2412750.4 | N10: ='Exercise 1'!K10 -> 511.2
A11: BQ94931 | B11: Oregon | C11: F | D11: College | E11: 738817.81 | F11: 28812 | G11: 93 | H11: 0 | I11: Special Auto | J11: Four-Door Car | K11: 425.52783 | L11: 35425.528 | M11: ='Exercise 1'!E11 -> 738817.81 | N11: ='Exercise 1'!K11 -> 425.52783
A12: SX51350 | B12: California | C12: M | D12: College | E12: 473899.2 | F12: 0 | G12: 67 | H12: 0 | I12: Personal Auto | J12: Four-Door Car | K12: 482.4 | L12: 35482.4 | M12: ='Exercise 1'!E12 -> 473899.2 | N12: ='Exercise 1'!K12 -> 482.4
A13: VQ65197 | B13: California | C13: NA | D13: College | E13: 819719.71 | F13: 0 | G13: 110 | H13: 0 | I13: Personal Auto | J13: SUV | K13: 528 | L13: 35528 | M13: ='Exercise 1'!E13 -> 819719.71 | N13: ='Exercise 1'!K13 -> 528
A14: DP39365 | B14: California | C14: NA | D14: Master | E14: 879879.7 | F14: 77026 | G14: 110 | H14: 36557 | I14: Corporate Auto | J14: Four-Door Car | K14: 472.02974 | L14: 35472.03 | M14: ='Exercise 1'!E14 -> 879879.7 | N14: ='Exercise 1'!K14 -> 472.02974
... A79: XW13033 | B79: Nevada | C79: NA | D79: College | E79: 800947.28 | F79: 20961 | G79: 67 | H79: 0 | I79: Personal Auto | J79: Four-Door Car | K79: 321.6 | L79: 35321.6 | M79: ='Exercise 1'!E79 -> 800947.28 | N79: ='Exercise 1'!K79 -> 321.6
A80: SP81997 | B80: Washington | C80: F | D80: Master | F80: 41275 | G80: 96 | H80: 0 | I80: Personal Auto | J80: Four-Door Car | K80: 41.122303 | L80: 35041.122 | M80: ='Exercise 1'!E80 -> 0 | N80: ='Exercise 1'!K80 -> 41.122303
A81: OM82309 | B81: California | C81: NA | D81: Bachelor | E81: 5816655.3 | F81: 61321 | G81: 186 | H81: 36526 | I81: Personal Auto | J81: Luxury Car | K81: 427.63121 | L81: 35427.631 | M81: ='Exercise 1'!E81 -> 5816655.3 | N81: ='Exercise 1'!K81 -> 427.63121
A82: ZU35962 | B82: California | C82: NA | D82: College | E82: 802522.94 | F82: 0 | G82: 77 | H82: 0 | I82: Personal Auto | J82: Two-Door Car | K82: 25.807685 | L82: 35025.808 | M82: ='Exercise 1'!E82 -> 802522.94 | N82: ='Exercise 1'!K82 -> 25.807685
A83: VH85817 | B83: California | C83: NA | D83: High School or Below | E83: 578018.22 | F83: 51066 | G83: 74 | H83: 0 | I83: Personal Auto | J83: Four-Door Car | K83: 787.99331 | L83: 35787.993 | M83: ='Exercise 1'!E83 -> 578018.22 | N83: ='Exercise 1'!K83 -> 787.99331
A84: DT85712 | B84: California | C84: NA | D84: Doctor | E84: 411853.91 | F84: 34378 | G84: 102 | H84: 0 | I84: Personal Auto | J84: SUV | K84: 489.6 | L84: 35489.6 | M84: ='Exercise 1'!E84 -> 411853.91 | N84: ='Exercise 1'!K84 -> 489.6
A85: YJ88573 | B85: Nevada | C85: NA | D85: Master | E85: 252307.02 | F85: 43072 | G85: 63 | H85: 0 | I85: Personal Auto | J85: Four-Door Car | K85: 302.4 | L85: 35302.4 | M85: ='Exercise 1'!E85 -> 252307.02 | N85: ='Exercise 1'!K85 -> 302.4
A86: SQ19467 | B86: Oregon | C86: NA | D86: College | E86: 655421.64 | F86: 25222 | G86: 90 | H86: 0 | I86: Personal Auto | J86: Four-Door Car | K86: 475.62325 | L86: 35475.623 | M86: ='Exercise 1'!E86 -> 655421.64 | N86: ='Exercise 1'!K86 -> 475.62325
A87: YB66933 | B87: Washington | C87: F | D87: Bachelor | E87: 538275.2 | F87: 77552 | G87: 68 | H87: 36526 | I87: Corporate Auto | J87: Four-Door Car | K87: 45.215059 | L87: 35045.215 | M87: ='Exercise 1'!E87 -> 538275.2 | N87: ='Exercise 1'!K87 -> 45.215059
A88: ET79815 | B88: California | C88: NA | D88: College | E88: 592672.94 | F88: 23091 | G88: 96 | H88: 36647 | I88: Personal Auto | J88: Four-Door Car | K88: 460.8 | L88: 35460.8 | M88: ='Exercise 1'!E88 -> 592672.94 | N88: ='Exercise 1'!K88 -> 460.8
A89: QC35222 | B89: California | C89: NA | D89: Bachelor | E89: 268347.07 | F89: 48269 | G89: 69 | H89: 36586 | I89: Corporate Auto | J89: Four-Door Car | K89: 282.15121 | L89: 35282.151 | M89: ='Exercise 1'!E89 -> 268347.07 | N89: ='Exercise 1'!K89 -> 282.15121
A90: CJ15590 | B90: Oregon | C90: NA | D90: Bachelor | E90: 269518.24 | F90: 32720 | G90: 67 | H90: 0 | I90: Personal Auto | J90: Four-Door Car | K90: 321.6 | L90: 35321.6 | M90: ='Exercise 1'!E90 -> 269518.24 | N90: ='Exercise 1'!K90 -> 321.6
A91: OI48267 | B91: California | C91: NA | D91: College | E91: 604702.52 | F91: 20396 | G91: 76 | H91: 36526 | I91: Personal Auto | J91: Four-Door Car | K91: 364.8 | L91: 35364.8 | M91: ='Exercise 1'!E91 -> 604702.52 | N91: ='Exercise 1'!K91 -> 364.8
A92: JY67916 | B92: Oregon | C92: NA | D92: College | E92: 1317101.3 | F92: 21513 | G92: 119 | H92: 36526 | I92: Personal Auto | J92: Two-Door Car | K92: 679.82759 | L92: 35679.828 | M92: ='Exercise 1'!E92 -> 1317101.3 | N92: ='Exercise 1'!K92 -> 679.82759
... A989: MB90871 | B989: Oregon | C989: F | D989: College | E989: 584741.52 | F989: 23496 | G989: 77 | H989: 0 | I989: Special Auto | J989: Four-Door Car | K989: 13.164097 | L989: 35013.164 | M989: ='Exercise 1'!E989 -> 584741.52 | N989: ='Exercise 1'!K989 -> 13.164097
A990: GT62080 | B990: Washington | C990: M | D990: High School or Below | F990: 55561 | G990: 63 | H990: 0 | I990: Personal Auto | J990: Four-Door Car | K990: 227.87207 | L990: 35227.872 | M990: ='Exercise 1'!E990 -> 0 | N990: ='Exercise 1'!K990 -> 227.87207
A991: QL77686 | B991: Nevada | C991: F | D991: College | E991: 472478.61 | F991: 23986 | G991: 119 | H991: 0 | I991: Corporate Auto | J991: SUV | K991: 463.33506 | L991: 35463.335 | M991: ='Exercise 1'!E991 -> 472478.61 | N991: ='Exercise 1'!K991 -> 463.33506
A992: ON77827 | B992: Arizona | C992: F | D992: Master | E992: 279022.8 | F992: 22974 | G992: 71 | H992: 0 | I992: Personal Auto | J992: Four-Door Car | K992: 180.66797 | L992: 35180.668 | M992: ='Exercise 1'!E992 -> 279022.8 | N992: ='Exercise 1'!K992 -> 180.66797
A993: KP18988 | B993: Oregon | C993: F | D993: High School or Below | E993: 2153133.3 | F993: 0 | G993: 101 | H993: 0 | I993: Personal Auto | J993: Four-Door Car | K993: 484.8 | L993: 35484.8 | M993: ='Exercise 1'!E993 -> 2153133.3 | N993: ='Exercise 1'!K993 -> 484.8
A994: TI92884 | B994: Arizona | C994: M | D994: Bachelor | E994: 1262283.3 | F994: 61844 | G994: 106 | H994: 0 | I994: Personal Auto | J994: Sports Car | K994: 508.8 | L994: 35508.8 | M994: ='Exercise 1'!E994 -> 1262283.3 | N994: ='Exercise 1'!K994 -> 508.8
A995: JH73503 | B995: Arizona | C995: M | D995: Doctor | E995: 2017196.1 | F995: 24804 | G995: 73 | H995: 0 | I995: Personal Auto | J995: Two-Door Car | K995: 350.4 | L995: 35350.4 | M995: ='Exercise 1'!E995 -> 2017196.1 | N995: ='Exercise 1'!K995 -> 350.4
A996: YE97964 | B996: Cali | C996: F | D996: Bachelor | E996: 1646436.6 | F996: 27760 | G996: 104 | H996: 0 | I996: Personal Auto | J996: SUV | K996: 302.76428 | L996: 35302.764 | M996: ='Exercise 1'!E996 -> 1646436.6 | N996: ='Exercise 1'!K996 -> 302.76428
A997: VA30351 | B997: Oregon | C997: F | D997: High School or Below | E997: 559538.99 | F997: 74454 | G997: 71 | H997: 0 | I997: Personal Auto | J997: Four-Door Car | K997: 340.8 | L997: 35340.8 | M997: ='Exercise 1'!E997 -> 559538.99 | N997: ='Exercise 1'!K997 -> 340.8
A998: PV55726 | B998: Oregon | C998: F | D998: Master | E998: 417068.73 | F998: 29462 | G998: 107 | H998: 36526 | I998: Personal Auto | J998: SUV | K998: 513.6 | L998: 35513.6 | M998: ='Exercise 1'!E998 -> 417068.73 | N998: ='Exercise 1'!K998 -> 513.6
A999: UC88305 | B999: Arizona | C999: F | D999: College | E999: 266544.71 | F999: 52266 | G999: 68 | H999: 0 | I999: Corporate Auto | J999: Two-Door Car | K999: 141.92284 | L999: 35141.923 | M999: ='Exercise 1'!E999 -> 266544.71 | N999: ='Exercise 1'!K999 -> 141.92284
A1000: TS53809 | B1000: Oregon | C1000: M | D1000: Bachelor | E1000: 709891.41 | F1000: 0 | G1000: 70 | H1000: 0 | I1000: Personal Auto | J1000: Two-Door Car | K1000: 349.78305 | L1000: 35349.783 | M1000: ='Exercise 1'!E1000 -> 709891.41 | N1000: ='Exercise 1'!K1000 -> 349.78305
...

Sheet Exercise 3
A1: Customer | B1: ST | C1: GENDER | D1: Education | E1: Customer Lifetime Value | F1: Income | G1: Monthly Premium Auto | H1: Number of Open Complaints | I1: Policy Type | J1: Vehicle Class | K1: Total Claim Amount | L1: Date
A2: RB50392 | B2: Washington | C2: NA | D2: Master | F2: 0 | G2: 1000 | H2: 0 | I2: Personal Auto | J2: Four-Door Car | K2: 2.704934 | L2: 35002.705 | M2: =LEFT(I2,FIND(" ",I2)-1) -> Personal
A3: QZ44356 | B3: Arizona | C3: F | D3: Bachelor | E3: 697953.59 | F3: 0 | G3: 94 | H3: 0 | I3: Personal Auto | J3: Four-Door Car | K3: 1131.4649 | L3: 36131.465 | M3: =LEFT(I3,FIND(" ",I3)-1) -> Personal
A4: AI49188 | B4: Nevada | C4: F | D4: Bachelor | E4: 1288743.2 | F4: 48767 | G4: 108 | H4: 0 | I4: Personal Auto | J4: Two-Door Car | K4: 566.47225 | L4: 35566.472 | M4: =LEFT(I4,FIND(" ",I4)-1) -> Personal
A5: WW63253 | B5: California | C5: M | D5: Bachelor | E5: 764586.18 | F5: 0 | G5: 106 | H5: 0 | I5: Corporate Auto | J5: SUV | K5: 529.88134 | L5: 35529.881 | M5: =LEFT(I5,FIND(" ",I5)-1) -> Corporate
A6: GA49547 | B6: Washington | C6: M | D6: High School or Below | E6: 536307.65 | F6: 36357 | G6: 68 | H6: 0 | I6: Personal Auto | J6: Four-Door Car | K6: 17.269323 | L6: 35017.269 | M6: =LEFT(I6,FIND(" ",I6)-1) -> Personal
A7: OC83172 | B7: Oregon | C7: F | D7: Bachelor | E7: 825629.78 | F7: 62902 | G7: 69 | H7: 0 | I7: Personal Auto | J7: Two-Door Car | K7: 159.38304 | L7: 35159.383 | M7: =LEFT(I7,FIND(" ",I7)-1) -> Personal
A8: XZ87318 | B8: Oregon | C8: F | D8: College | E8: 538089.86 | F8: 55350 | G8: 67 | H8: 0 | I8: Corporate Auto | J8: Four-Door Car | K8: 321.6 | L8: 35321.6 | M8: =LEFT(I8,FIND(" ",I8)-1) -> Corporate
A9: CF85061 | B9: Arizona | C9: M | D9: Master | E9: 721610.03 | F9: 0 | G9: 101 | H9: 0 | I9: Corporate Auto | J9: Four-Door Car | K9: 363.02968 | L9: 35363.03 | M9: =LEFT(I9,FIND(" ",I9)-1) -> Corporate
A10: DY87989 | B10: Oregon | C10: M | D10: Bachelor | E10: 2412750.4 | F10: 14072 | G10: 71 | H10: 0 | I10: Corporate Auto | J10: Four-Door Car | K10: 511.2 | L10: 35511.2 | M10: =LEFT(I10,FIND(" ",I10)-1) -> Corporate
A11: BQ94931 | B11: Oregon | C11: F | D11: College | E11: 738817.81 | F11: 28812 | G11: 93 | H11: 0 | I11: Special Auto | J11: Four-Door Car | K11: 425.52783 | L11: 35425.528 | M11: =LEFT(I11,FIND(" ",I11)-1) -> Special
A12: SX51350 | B12: California | C12: M | D12: College | E12: 473899.2 | F12: 0 | G12: 67 | H12: 0 | I12: Personal Auto | J12: Four-Door Car | K12: 482.4 | L12: 35482.4 | M12: =LEFT(I12,FIND(" ",I12)-1) -> Personal
A13: VQ65197 | B13: California | C13: NA | D13: College | E13: 819719.71 | F13: 0 | G13: 110 | H13: 0 | I13: Personal Auto | J13: SUV | K13: 528 | L13: 35528 | M13: =LEFT(I13,FIND(" ",I13)-1) -> Personal
A14: DP39365 | B14: California | C14: NA | D14: Master | E14: 879879.7 | F14: 77026 | G14: 110 | H14: 36557 | I14: Corporate Auto | J14: Four-Door Car | K14: 472.02974 | L14: 35472.03 | M14: =LEFT(I14,FIND(" ",I14)-1) -> Corporate
... A79: XW13033 | B79: Nevada | C79: NA | D79: College | E79: 800947.28 | F79: 20961 | G79: 67 | H79: 0 | I79: Personal Auto | J79: Four-Door Car | K79: 321.6 | L79: 35321.6 | M79: =LEFT(I79,FIND(" ",I79)-1) -> Personal
A80: SP81997 | B80: Washington | C80: F | D80: Master | F80: 41275 | G80: 96 | H80: 0 | I80: Personal Auto | J80: Four-Door Car | K80: 41.122303 | L80: 35041.122 | M80: =LEFT(I80,FIND(" ",I80)-1) -> Personal
A81: OM82309 | B81: California | C81: NA | D81: Bachelor | E81: 5816655.3 | F81: 61321 | G81: 186 | H81: 36526 | I81: Personal Auto | J81: Luxury Car | K81: 427.63121 | L81: 35427.631 | M81: =LEFT(I81,FIND(" ",I81)-1) -> Personal
A82: ZU35962 | B82: California | C82: NA | D82: College | E82: 802522.94 | F82: 0 | G82: 77 | H82: 0 | I82: Personal Auto | J82: Two-Door Car | K82: 25.807685 | L82: 35025.808 | M82: =LEFT(I82,FIND(" ",I82)-1) -> Personal
A83: VH85817 | B83: California | C83: NA | D83: High School or Below | E83: 578018.22 | F83: 51066 | G83: 74 | H83: 0 | I83: Personal Auto | J83: Four-Door Car | K83: 787.99331 | L83: 35787.993 | M83: =LEFT(I83,FIND(" ",I83)-1) -> Personal
A84: DT85712 | B84: California | C84: NA | D84: Doctor | E84: 411853.91 | F84: 34378 | G84: 102 | H84: 0 | I84: Personal Auto | J84: SUV | K84: 489.6 | L84: 35489.6 | M84: =LEFT(I84,FIND(" ",I84)-1) -> Personal
A85: YJ88573 | B85: Nevada | C85: NA | D85: Master | E85: 252307.02 | F85: 43072 | G85: 63 | H85: 0 | I85: Personal Auto | J85: Four-Door Car | K85: 302.4 | L85: 35302.4 | M85: =LEFT(I85,FIND(" ",I85)-1) -> Personal
A86: SQ19467 | B86: Oregon | C86: NA | D86: College | E86: 655421.64 | F86: 25222 | G86: 90 | H86: 0 | I86: Personal Auto | J86: Four-Door Car | K86: 475.62325 | L86: 35475.623 | M86: =LEFT(I86,FIND(" ",I86)-1) -> Personal
A87: YB66933 | B87: Washington | C87: F | D87: Bachelor | E87: 538275.2 | F87: 77552 | G87: 68 | H87: 36526 | I87: Corporate Auto | J87: Four-Door Car | K87: 45.215059 | L87: 35045.215 | M87: =LEFT(I87,FIND(" ",I87)-1) -> Corporate
A88: ET79815 | B88: California | C88: NA | D88: College | E88: 592672.94 | F88: 23091 | G88: 96 | H88: 36647 | I88: Personal Auto | J88: Four-Door Car | K88: 460.8 | L88: 35460.8 | M88: =LEFT(I88,FIND(" ",I88)-1) -> Personal
A89: QC35222 | B89: California | C89: NA | D89: Bachelor | E89: 268347.07 | F89: 48269 | G89: 69 | H89: 36586 | I89: Corporate Auto | J89: Four-Door Car | K89: 282.15121 | L89: 35282.151 | M89: =LEFT(I89,FIND(" ",I89)-1) -> Corporate
A90: CJ15590 | B90: Oregon | C90: NA | D90: Bachelor | E90: 269518.24 | F90: 32720 | G90: 67 | H90: 0 | I90: Personal Auto | J90: Four-Door Car | K90: 321.6 | L90: 35321.6 | M90: =LEFT(I90,FIND(" ",I90)-1) -> Personal
A91: OI48267 | B91: California | C91: NA | D91: College | E91: 604702.52 | F91: 20396 | G91: 76 | H91: 36526 | I91: Personal Auto | J91: Four-Door Car | K91: 364.8 | L91: 35364.8 | M91: =LEFT(I91,FIND(" ",I91)-1) -> Personal
A92: JY67916 | B92: Oregon | C92: NA | D92: College | E92: 1317101.3 | F92: 21513 | G92: 119 | H92: 36526 | I92: Personal Auto | J92: Two-Door Car | K92: 679.82759 | L92: 35679.828 | M92: =LEFT(I92,FIND(" ",I92)-1) -> Personal
... A989: MB90871 | B989: Oregon | C989: F | D989: College | E989: 584741.52 | F989: 23496 | G989: 77 | H989: 0 | I989: Special Auto | J989: Four-Door Car | K989: 13.164097 | L989: 35013.164 | M989: =LEFT(I989,FIND(" ",I989)-1) -> Special
A990: GT62080 | B990: Washington | C990: M | D990: High School or Below | F990: 55561 | G990: 63 | H990: 0 | I990: Personal Auto | J990: Four-Door Car | K990: 227.87207 | L990: 35227.872 | M990: =LEFT(I990,FIND(" ",I990)-1) -> Personal
A991: QL77686 | B991: Nevada | C991: F | D991: College | E991: 472478.61 | F991: 23986 | G991: 119 | H991: 0 | I991: Corporate Auto | J991: SUV | K991: 463.33506 | L991: 35463.335 | M991: =LEFT(I991,FIND(" ",I991)-1) -> Corporate
A992: ON77827 | B992: Arizona | C992: F | D992: Master | E992: 279022.8 | F992: 22974 | G992: 71 | H992: 0 | I992: Personal Auto | J992: Four-Door Car | K992: 180.66797 | L992: 35180.668 | M992: =LEFT(I992,FIND(" ",I992)-1) -> Personal
A993: KP18988 | B993: Oregon | C993: F | D993: High School or Below | E993: 2153133.3 | F993: 0 | G993: 101 | H993: 0 | I993: Personal Auto | J993: Four-Door Car | K993: 484.8 | L993: 35484.8 | M993: =LEFT(I993,FIND(" ",I993)-1) -> Personal
A994: TI92884 | B994: Arizona | C994: M | D994: Bachelor | E994: 1262283.3 | F994: 61844 | G994: 106 | H994: 0 | I994: Personal Auto | J994: Sports Car | K994: 508.8 | L994: 35508.8 | M994: =LEFT(I994,FIND(" ",I994)-1) -> Personal
A995: JH73503 | B995: Arizona | C995: M | D995: Doctor | E995: 2017196.1 | F995: 24804 | G995: 73 | H995: 0 | I995: Personal Auto | J995: Two-Door Car | K995: 350.4 | L995: 35350.4 | M995: =LEFT(I995,FIND(" ",I995)-1) -> Personal
A996: YE97964 | B996: Cali | C996: F | D996: Bachelor | E996: 1646436.6 | F996: 27760 | G996: 104 | H996: 0 | I996: Personal Auto | J996: SUV | K996: 302.76428 | L996: 35302.764 | M996: =LEFT(I996,FIND(" ",I996)-1) -> Personal
A997: VA30351 | B997: Oregon | C997: F | D997: High School or Below | E997: 559538.99 | F997: 74454 | G997: 71 | H997: 0 | I997: Personal Auto | J997: Four-Door Car | K997: 340.8 | L997: 35340.8 | M997: =LEFT(I997,FIND(" ",I997)-1) -> Personal
A998: PV55726 | B998: Oregon | C998: F | D998: Master | E998: 417068.73 | F998: 29462 | G998: 107 | H998: 36526 | I998: Personal Auto | J998: SUV | K998: 513.6 | L998: 35513.6 | M998: =LEFT(I998,FIND(" ",I998)-1) -> Personal
A999: UC88305 | B999: Arizona | C999: F | D999: College | E999: 266544.71 | F999: 52266 | G999: 68 | H999: 0 | I999: Corporate Auto | J999: Two-Door Car | K999: 141.92284 | L999: 35141.923 | M999: =LEFT(I999,FIND(" ",I999)-1) -> Corporate
A1000: TS53809 | B1000: Oregon | C1000: M | D1000: Bachelor | E1000: 709891.41 | F1000: 0 | G1000: 70 | H1000: 0 | I1000: Personal Auto | J1000: Two-Door Car | K1000: 349.78305 | L1000: 35349.783 | M1000: =LEFT(I1000,FIND(" ",I1000)-1) -> Personal
...

Sheet Exercise 4
A1: Customer | B1: ST | C1: GENDER | D1: Education | E1: Customer Lifetime Value | F1: Income | G1: Monthly Premium Auto | H1: Number of Open Complaints | I1: Policy Type | J1: Vehicle Class | K1: Total Claim Amount | L1: Date
A2: RB50392 | B2: Washington | C2: NA | D2: Master | F2: 0 | G2: 1000 | H2: 0 | I2: Personal Auto | J2: Four-Door Car | K2: 2.704934 | L2: 35002.705 | M2: =IF(OR(J2="Luxury Car",J2="Two-Door Car",J2="Sports Car"),2,IF(OR(J2="Luxury SUV",J2="SUV",J2="Four-Door Car"),4,"NA")) -> 4
A3: QZ44356 | B3: Arizona | C3: F | D3: Bachelor | E3: 697953.59 | F3: 0 | G3: 94 | H3: 0 | I3: Personal Auto | J3: Four-Door Car | K3: 1131.4649 | L3: 36131.465 | M3: =IF(OR(J3="Luxury Car",J3="Two-Door Car",J3="Sports Car"),2,IF(OR(J3="Luxury SUV",J3="SUV",J3="Four-Door Car"),4,"NA")) -> 4
A4: AI49188 | B4: Nevada | C4: F | D4: Bachelor | E4: 1288743.2 | F4: 48767 | G4: 108 | H4: 0 | I4: Personal Auto | J4: Two-Door Car | K4: 566.47225 | L4: 35566.472 | M4: =IF(OR(J4="Luxury Car",J4="Two-Door Car",J4="Sports Car"),2,IF(OR(J4="Luxury SUV",J4="SUV",J4="Four-Door Car"),4,"NA")) -> 2
A5: WW63253 | B5: California | C5: M | D5: Bachelor | E5: 764586.18 | F5: 0 | G5: 106 | H5: 0 | I5: Corporate Auto | J5: SUV | K5: 529.88134 | L5: 35529.881 | M5: =IF(OR(J5="Luxury Car",J5="Two-Door Car",J5="Sports Car"),2,IF(OR(J5="Luxury SUV",J5="SUV",J5="Four-Door Car"),4,"NA")) -> 4
A6: GA49547 | B6: Washington | C6: M | D6: High School or Below | E6: 536307.65 | F6: 36357 | G6: 68 | H6: 0 | I6: Personal Auto | J6: Four-Door Car | K6: 17.269323 | L6: 35017.269 | M6: =IF(OR(J6="Luxury Car",J6="Two-Door Car",J6="Sports Car"),2,IF(OR(J6="Luxury SUV",J6="SUV",J6="Four-Door Car"),4,"NA")) -> 4
A7: OC83172 | B7: Oregon | C7: F | D7: Bachelor | E7: 825629.78 | F7: 62902 | G7: 69 | H7: 0 | I7: Personal Auto | J7: Two-Door Car | K7: 159.38304 | L7: 35159.383 | M7: =IF(OR(J7="Luxury Car",J7="Two-Door Car",J7="Sports Car"),2,IF(OR(J7="Luxury SUV",J7="SUV",J7="Four-Door Car"),4,"NA")) -> 2
A8: XZ87318 | B8: Oregon | C8: F | D8: College | E8: 538089.86 | F8: 55350 | G8: 67 | H8: 0 | I8: Corporate Auto | J8: Four-Door Car | K8: 321.6 | L8: 35321.6 | M8: =IF(OR(J8="Luxury Car",J8="Two-Door Car",J8="Sports Car"),2,IF(OR(J8="Luxury SUV",J8="SUV",J8="Four-Door Car"),4,"NA")) -> 4
A9: CF85061 | B9: Arizona | C9: M | D9: Master | E9: 721610.03 | F9: 0 | G9: 101 | H9: 0 | I9: Corporate Auto | J9: Four-Door Car | K9: 363.02968 | L9: 35363.03 | M9: =IF(OR(J9="Luxury Car",J9="Two-Door Car",J9="Sports Car"),2,IF(OR(J9="Luxury SUV",J9="SUV",J9="Four-Door Car"),4,"NA")) -> 4
A10: DY87989 | B10: Oregon | C10: M | D10: Bachelor | E10: 2412750.4 | F10: 14072 | G10: 71 | H10: 0 | I10: Corporate Auto | J10: Four-Door Car | K10: 511.2 | L10: 35511.2 | M10: =IF(OR(J10="Luxury Car",J10="Two-Door Car",J10="Sports Car"),2,IF(OR(J10="Luxury SUV",J10="SUV",J10="Four-Door Car"),4,"NA")) -> 4
A11: BQ94931 | B11: Oregon | C11: F | D11: College | E11: 738817.81 | F11: 28812 | G11: 93 | H11: 0 | I11: Special Auto | J11: Four-Door Car | K11: 425.52783 | L11: 35425.528 | M11: =IF(OR(J11="Luxury Car",J11="Two-Door Car",J11="Sports Car"),2,IF(OR(J11="Luxury SUV",J11="SUV",J11="Four-Door Car"),4,"NA")) -> 4
A12: SX51350 | B12: California | C12: M | D12: College | E12: 473899.2 | F12: 0 | G12: 67 | H12: 0 | I12: Personal Auto | J12: Four-Door Car | K12: 482.4 | L12: 35482.4 | M12: =IF(OR(J12="Luxury Car",J12="Two-Door Car",J12="Sports Car"),2,IF(OR(J12="Luxury SUV",J12="SUV",J12="Four-Door Car"),4,"NA")) -> 4
A13: VQ65197 | B13: California | C13: NA | D13: College | E13: 819719.71 | F13: 0 | G13: 110 | H13: 0 | I13: Personal Auto | J13: SUV | K13: 528 | L13: 35528 | M13: =IF(OR(J13="Luxury Car",J13="Two-Door Car",J13="Sports Car"),2,IF(OR(J13="Luxury SUV",J13="SUV",J13="Four-Door Car"),4,"NA")) -> 4
A14: DP39365 | B14: California | C14: NA | D14: Master | E14: 879879.7 | F14: 77026 | G14: 110 | H14: 36557 | I14: Corporate Auto | J14: Four-Door Car | K14: 472.02974 | L14: 35472.03 | M14: =IF(OR(J14="Luxury Car",J14="Two-Door Car",J14="Sports Car"),2,IF(OR(J14="Luxury SUV",J14="SUV",J14="Four-Door Car"),4,"NA")) -> 4
... A79: XW13033 | B79: Nevada | C79: NA | D79: College | E79: 800947.28 | F79: 20961 | G79: 67 | H79: 0 | I79: Personal Auto | J79: Four-Door Car | K79: 321.6 | L79: 35321.6 | M79: =IF(OR(J79="Luxury Car",J79="Two-Door Car",J79="Sports Car"),2,IF(OR(J79="Luxury SUV",J79="SUV",J79="Four-Door Car"),4,"NA")) -> 4
A80: SP81997 | B80: Washington | C80: F | D80: Master | F80: 41275 | G80: 96 | H80: 0 | I80: Personal Auto | J80: Four-Door Car | K80: 41.122303 | L80: 35041.122 | M80: =IF(OR(J80="Luxury Car",J80="Two-Door Car",J80="Sports Car"),2,IF(OR(J80="Luxury SUV",J80="SUV",J80="Four-Door Car"),4,"NA")) -> 4
A81: OM82309 | B81: California | C81: NA | D81: Bachelor | E81: 5816655.3 | F81: 61321 | G81: 186 | H81: 36526 | I81: Personal Auto | J81: Luxury Car | K81: 427.63121 | L81: 35427.631 | M81: =IF(OR(J81="Luxury Car",J81="Two-Door Car",J81="Sports Car"),2,IF(OR(J81="Luxury SUV",J81="SUV",J81="Four-Door Car"),4,"NA")) -> 2
A82: ZU35962 | B82: California | C82: NA | D82: College | E82: 802522.94 | F82: 0 | G82: 77 | H82: 0 | I82: Personal Auto | J82: Two-Door Car | K82: 25.807685 | L82: 35025.808 | M82: =IF(OR(J82="Luxury Car",J82="Two-Door Car",J82="Sports Car"),2,IF(OR(J82="Luxury SUV",J82="SUV",J82="Four-Door Car"),4,"NA")) -> 2
A83: VH85817 | B83: California | C83: NA | D83: High School or Below | E83: 578018.22 | F83: 51066 | G83: 74 | H83: 0 | I83: Personal Auto | J83: Four-Door Car | K83: 787.99331 | L83: 35787.993 | M83: =IF(OR(J83="Luxury Car",J83="Two-Door Car",J83="Sports Car"),2,IF(OR(J83="Luxury SUV",J83="SUV",J83="Four-Door Car"),4,"NA")) -> 4
A84: DT85712 | B84: California | C84: NA | D84: Doctor | E84: 411853.91 | F84: 34378 | G84: 102 | H84: 0 | I84: Personal Auto | J84: SUV | K84: 489.6 | L84: 35489.6 | M84: =IF(OR(J84="Luxury Car",J84="Two-Door Car",J84="Sports Car"),2,IF(OR(J84="Luxury SUV",J84="SUV",J84="Four-Door Car"),4,"NA")) -> 4
A85: YJ88573 | B85: Nevada | C85: NA | D85: Master | E85: 252307.02 | F85: 43072 | G85: 63 | H85: 0 | I85: Personal Auto | J85: Four-Door Car | K85: 302.4 | L85: 35302.4 | M85: =IF(OR(J85="Luxury Car",J85="Two-Door Car",J85="Sports Car"),2,IF(OR(J85="Luxury SUV",J85="SUV",J85="Four-Door Car"),4,"NA")) -> 4
A86: SQ19467 | B86: Oregon | C86: NA | D86: College | E86: 655421.64 | F86: 25222 | G86: 90 | H86: 0 | I86: Personal Auto | J86: Four-Door Car | K86: 475.62325 | L86: 35475.623 | M86: =IF(OR(J86="Luxury Car",J86="Two-Door Car",J86="Sports Car"),2,IF(OR(J86="Luxury SUV",J86="SUV",J86="Four-Door Car"),4,"NA")) -> 4
A87: YB66933 | B87: Washington | C87: F | D87: Bachelor | E87: 538275.2 | F87: 77552 | G87: 68 | H87: 36526 | I87: Corporate Auto | J87: Four-Door Car | K87: 45.215059 | L87: 35045.215 | M87: =IF(OR(J87="Luxury Car",J87="Two-Door Car",J87="Sports Car"),2,IF(OR(J87="Luxury SUV",J87="SUV",J87="Four-Door Car"),4,"NA")) -> 4
A88: ET79815 | B88: California | C88: NA | D88: College | E88: 592672.94 | F88: 23091 | G88: 96 | H88: 36647 | I88: Personal Auto | J88: Four-Door Car | K88: 460.8 | L88: 35460.8 | M88: =IF(OR(J88="Luxury Car",J88="Two-Door Car",J88="Sports Car"),2,IF(OR(J88="Luxury SUV",J88="SUV",J88="Four-Door Car"),4,"NA")) -> 4
A89: QC35222 | B89: California | C89: NA | D89: Bachelor | E89: 268347.07 | F89: 48269 | G89: 69 | H89: 36586 | I89: Corporate Auto | J89: Four-Door Car | K89: 282.15121 | L89: 35282.151 | M89: =IF(OR(J89="Luxury Car",J89="Two-Door Car",J89="Sports Car"),2,IF(OR(J89="Luxury SUV",J89="SUV",J89="Four-Door Car"),4,"NA")) -> 4
A90: CJ15590 | B90: Oregon | C90: NA | D90: Bachelor | E90: 269518.24 | F90: 32720 | G90: 67 | H90: 0 | I90: Personal Auto | J90: Four-Door Car | K90: 321.6 | L90: 35321.6 | M90: =IF(OR(J90="Luxury Car",J90="Two-Door Car",J90="Sports Car"),2,IF(OR(J90="Luxury SUV",J90="SUV",J90="Four-Door Car"),4,"NA")) -> 4
A91: OI48267 | B91: California | C91: NA | D91: College | E91: 604702.52 | F91: 20396 | G91: 76 | H91: 36526 | I91: Personal Auto | J91: Four-Door Car | K91: 364.8 | L91: 35364.8 | M91: =IF(OR(J91="Luxury Car",J91="Two-Door Car",J91="Sports Car"),2,IF(OR(J91="Luxury SUV",J91="SUV",J91="Four-Door Car"),4,"NA")) -> 4
A92: JY67916 | B92: Oregon | C92: NA | D92: College | E92: 1317101.3 | F92: 21513 | G92: 119 | H92: 36526 | I92: Personal Auto | J92: Two-Door Car | K92: 679.82759 | L92: 35679.828 | M92: =IF(OR(J92="Luxury Car",J92="Two-Door Car",J92="Sports Car"),2,IF(OR(J92="Luxury SUV",J92="SUV",J92="Four-Door Car"),4,"NA")) -> 2
... A989: MB90871 | B989: Oregon | C989: F | D989: College | E989: 584741.52 | F989: 23496 | G989: 77 | H989: 0 | I989: Special Auto | J989: Four-Door Car | K989: 13.164097 | L989: 35013.164 | M989: =IF(OR(J989="Luxury Car",J989="Two-Door Car",J989="Sports Car"),2,IF(OR(J989="Luxury SUV",J989="SUV",J989="Four-Door Car"),4,"NA")) -> 4
A990: GT62080 | B990: Washington | C990: M | D990: High School or Below | F990: 55561 | G990: 63 | H990: 0 | I990: Personal Auto | J990: Four-Door Car | K990: 227.87207 | L990: 35227.872 | M990: =IF(OR(J990="Luxury Car",J990="Two-Door Car",J990="Sports Car"),2,IF(OR(J990="Luxury SUV",J990="SUV",J990="Four-Door Car"),4,"NA")) -> 4
A991: QL77686 | B991: Nevada | C991: F | D991: College | E991: 472478.61 | F991: 23986 | G991: 119 | H991: 0 | I991: Corporate Auto | J991: SUV | K991: 463.33506 | L991: 35463.335 | M991: =IF(OR(J991="Luxury Car",J991="Two-Door Car",J991="Sports Car"),2,IF(OR(J991="Luxury SUV",J991="SUV",J991="Four-Door Car"),4,"NA")) -> 4
A992: ON77827 | B992: Arizona | C992: F | D992: Master | E992: 279022.8 | F992: 22974 | G992: 71 | H992: 0 | I992: Personal Auto | J992: Four-Door Car | K992: 180.66797 | L992: 35180.668 | M992: =IF(OR(J992="Luxury Car",J992="Two-Door Car",J992="Sports Car"),2,IF(OR(J992="Luxury SUV",J992="SUV",J992="Four-Door Car"),4,"NA")) -> 4
A993: KP18988 | B993: Oregon | C993: F | D993: High School or Below | E993: 2153133.3 | F993: 0 | G993: 101 | H993: 0 | I993: Personal Auto | J993: Four-Door Car | K993: 484.8 | L993: 35484.8 | M993: =IF(OR(J993="Luxury Car",J993="Two-Door Car",J993="Sports Car"),2,IF(OR(J993="Luxury SUV",J993="SUV",J993="Four-Door Car"),4,"NA")) -> 4
A994: TI92884 | B994: Arizona | C994: M | D994: Bachelor | E994: 1262283.3 | F994: 61844 | G994: 106 | H994: 0 | I994: Personal Auto | J994: Sports Car | K994: 508.8 | L994: 35508.8 | M994: =IF(OR(J994="Luxury Car",J994="Two-Door Car",J994="Sports Car"),2,IF(OR(J994="Luxury SUV",J994="SUV",J994="Four-Door Car"),4,"NA")) -> 2
A995: JH73503 | B995: Arizona | C995: M | D995: Doctor | E995: 2017196.1 | F995: 24804 | G995: 73 | H995: 0 | I995: Personal Auto | J995: Two-Door Car | K995: 350.4 | L995: 35350.4 | M995: =IF(OR(J995="Luxury Car",J995="Two-Door Car",J995="Sports Car"),2,IF(OR(J995="Luxury SUV",J995="SUV",J995="Four-Door Car"),4,"NA")) -> 2
A996: YE97964 | B996: Cali | C996: F | D996: Bachelor | E996: 1646436.6 | F996: 27760 | G996: 104 | H996: 0 | I996: Personal Auto | J996: SUV | K996: 302.76428 | L996: 35302.764 | M996: =IF(OR(J996="Luxury Car",J996="Two-Door Car",J996="Sports Car"),2,IF(OR(J996="Luxury SUV",J996="SUV",J996="Four-Door Car"),4,"NA")) -> 4
A997: VA30351 | B997: Oregon | C997: F | D997: High School or Below | E997: 559538.99 | F997: 74454 | G997: 71 | H997: 0 | I997: Personal Auto | J997: Four-Door Car | K997: 340.8 | L997: 35340.8 | M997: =IF(OR(J997="Luxury Car",J997="Two-Door Car",J997="Sports Car"),2,IF(OR(J997="Luxury SUV",J997="SUV",J997="Four-Door Car"),4,"NA")) -> 4
A998: PV55726 | B998: Oregon | C998: F | D998: Master | E998: 417068.73 | F998: 29462 | G998: 107 | H998: 36526 | I998: Personal Auto | J998: SUV | K998: 513.6 | L998: 35513.6 | M998: =IF(OR(J998="Luxury Car",J998="Two-Door Car",J998="Sports Car"),2,IF(OR(J998="Luxury SUV",J998="SUV",J998="Four-Door Car"),4,"NA")) -> 4
A999: UC88305 | B999: Arizona | C999: F | D999: College | E999: 266544.71 | F999: 52266 | G999: 68 | H999: 0 | I999: Corporate Auto | J999: Two-Door Car | K999: 141.92284 | L999: 35141.923 | M999: =IF(OR(J999="Luxury Car",J999="Two-Door Car",J999="Sports Car"),2,IF(OR(J999="Luxury SUV",J999="SUV",J999="Four-Door Car"),4,"NA")) -> 2
A1000: TS53809 | B1000: Oregon | C1000: M | D1000: Bachelor | E1000: 709891.41 | F1000: 0 | G1000: 70 | H1000: 0 | I1000: Personal Auto | J1000: Two-Door Car | K1000: 349.78305 | L1000: 35349.783 | M1000: =IF(OR(J1000="Luxury Car",J1000="Two-Door Car",J1000="Sports Car"),2,IF(OR(J1000="Luxury SUV",J1000="SUV",J1000="Four-Door Car"),4,"NA")) -> 2
...

Sheet Exercise 5
A1: Customer | B1: ST | C1: GENDER | D1: Education | E1: Customer Lifetime Value | F1: Income | G1: Monthly Premium Auto | H1: Number of Open Complaints | I1: Policy Type | J1: Vehicle Class | K1: Total Claim Amount | L1: Date
A2: RB50392 | B2: Washington | C2: NA | D2: Master | F2: 0 | G2: 1000 | H2: 0 | I2: Personal Auto | J2: Four-Door Car | K2: 2.704934 | L2: 35002.705 | M2: =DATEDIF(L2,TODAY(),"Y") -> 30
A3: QZ44356 | B3: Arizona | C3: F | D3: Bachelor | E3: 697953.59 | F3: 0 | G3: 94 | H3: 0 | I3: Personal Auto | J3: Four-Door Car | K3: 1131.4649 | L3: 36131.465 | M3: =DATEDIF(L3,TODAY(),"Y") -> 27
A4: AI49188 | B4: Nevada | C4: F | D4: Bachelor | E4: 1288743.2 | F4: 48767 | G4: 108 | H4: 0 | I4: Personal Auto | J4: Two-Door Car | K4: 566.47225 | L4: 35566.472 | M4: =DATEDIF(L4,TODAY(),"Y") -> 29
A5: WW63253 | B5: California | C5: M | D5: Bachelor | E5: 764586.18 | F5: 0 | G5: 106 | H5: 0 | I5: Corporate Auto | J5: SUV | K5: 529.88134 | L5: 35529.881 | M5: =DATEDIF(L5,TODAY(),"Y") -> 29
A6: GA49547 | B6: Washington | C6: M | D6: High School or Below | E6: 536307.65 | F6: 36357 | G6: 68 | H6: 0 | I6: Personal Auto | J6: Four-Door Car | K6: 17.269323 | L6: 35017.269 | M6: =DATEDIF(L6,TODAY(),"Y") -> 30
A7: OC83172 | B7: Oregon | C7: F | D7: Bachelor | E7: 825629.78 | F7: 62902 | G7: 69 | H7: 0 | I7: Personal Auto | J7: Two-Door Car | K7: 159.38304 | L7: 35159.383 | M7: =DATEDIF(L7,TODAY(),"Y") -> 30
A8: XZ87318 | B8: Oregon | C8: F | D8: College | E8: 538089.86 | F8: 55350 | G8: 67 | H8: 0 | I8: Corporate Auto | J8: Four-Door Car | K8: 321.6 | L8: 35321.6 | M8: =DATEDIF(L8,TODAY(),"Y") -> 29
A9: CF85061 | B9: Arizona | C9: M | D9: Master | E9: 721610.03 | F9: 0 | G9: 101 | H9: 0 | I9: Corporate Auto | J9: Four-Door Car | K9: 363.02968 | L9: 35363.03 | M9: =DATEDIF(L9,TODAY(),"Y") -> 29
A10: DY87989 | B10: Oregon | C10: M | D10: Bachelor | E10: 2412750.4 | F10: 14072 | G10: 71 | H10: 0 | I10: Corporate Auto | J10: Four-Door Car | K10: 511.2 | L10: 35511.2 | M10: =DATEDIF(L10,TODAY(),"Y") -> 29
A11: BQ94931 | B11: Oregon | C11: F | D11: College | E11: 738817.81 | F11: 28812 | G11: 93 | H11: 0 | I11: Special Auto | J11: Four-Door Car | K11: 425.52783 | L11: 35425.528 | M11: =DATEDIF(L11,TODAY(),"Y") -> 29
A12: SX51350 | B12: California | C12: M | D12: College | E12: 473899.2 | F12: 0 | G12: 67 | H12: 0 | I12: Personal Auto | J12: Four-Door Car | K12: 482.4 | L12: 35482.4 | M12: =DATEDIF(L12,TODAY(),"Y") -> 29
A13: VQ65197 | B13: California | C13: NA | D13: College | E13: 819719.71 | F13: 0 | G13: 110 | H13: 0 | I13: Personal Auto | J13: SUV | K13: 528 | L13: 35528 | M13: =DATEDIF(L13,TODAY(),"Y") -> 29
A14: DP39365 | B14: California | C14: NA | D14: Master | E14: 879879.7 | F14: 77026 | G14: 110 | H14: 36557 | I14: Corporate Auto | J14: Four-Door Car | K14: 472.02974 | L14: 35472.03 | M14: =DATEDIF(L14,TODAY(),"Y") -> 29
... A79: XW13033 | B79: Nevada | C79: NA | D79: College | E79: 800947.28 | F79: 20961 | G79: 67 | H79: 0 | I79: Personal Auto | J79: Four-Door Car | K79: 321.6 | L79: 35321.6 | M79: =DATEDIF(L79,TODAY(),"Y") -> 29
A80: SP81997 | B80: Washington | C80: F | D80: Master | F80: 41275 | G80: 96 | H80: 0 | I80: Personal Auto | J80: Four-Door Car | K80: 41.122303 | L80: 35041.122 | M80: =DATEDIF(L80,TODAY(),"Y") -> 30
A81: OM82309 | B81: California | C81: NA | D81: Bachelor | E81: 5816655.3 | F81: 61321 | G81: 186 | H81: 36526 | I81: Personal Auto | J81: Luxury Car | K81: 427.63121 | L81: 35427.631 | M81: =DATEDIF(L81,TODAY(),"Y") -> 29
A82: ZU35962 | B82: California | C82: NA | D82: College | E82: 802522.94 | F82: 0 | G82: 77 | H82: 0 | I82: Personal Auto | J82: Two-Door Car | K82: 25.807685 | L82: 35025.808 | M82: =DATEDIF(L82,TODAY(),"Y") -> 30
A83: VH85817 | B83: California | C83: NA | D83: High School or Below | E83: 578018.22 | F83: 51066 | G83: 74 | H83: 0 | I83: Personal Auto | J83: Four-Door Car | K83: 787.99331 | L83: 35787.993 | M83: =DATEDIF(L83,TODAY(),"Y") -> 28
A84: DT85712 | B84: California | C84: NA | D84: Doctor | E84: 411853.91 | F84: 34378 | G84: 102 | H84: 0 | I84: Personal Auto | J84: SUV | K84: 489.6 | L84: 35489.6 | M84: =DATEDIF(L84,TODAY(),"Y") -> 29
A85: YJ88573 | B85: Nevada | C85: NA | D85: Master | E85: 252307.02 | F85: 43072 | G85: 63 | H85: 0 | I85: Personal Auto | J85: Four-Door Car | K85: 302.4 | L85: 35302.4 | M85: =DATEDIF(L85,TODAY(),"Y") -> 30
A86: SQ19467 | B86: Oregon | C86: NA | D86: College | E86: 655421.64 | F86: 25222 | G86: 90 | H86: 0 | I86: Personal Auto | J86: Four-Door Car | K86: 475.62325 | L86: 35475.623 | M86: =DATEDIF(L86,TODAY(),"Y") -> 29
A87: YB66933 | B87: Washington | C87: F | D87: Bachelor | E87: 538275.2 | F87: 77552 | G87: 68 | H87: 36526 | I87: Corporate Auto | J87: Four-Door Car | K87: 45.215059 | L87: 35045.215 | M87: =DATEDIF(L87,TODAY(),"Y") -> 30
A88: ET79815 | B88: California | C88: NA | D88: College | E88: 592672.94 | F88: 23091 | G88: 96 | H88: 36647 | I88: Personal Auto | J88: Four-Door Car | K88: 460.8 | L88: 35460.8 | M88: =DATEDIF(L88,TODAY(),"Y") -> 29
A89: QC35222 | B89: California | C89: NA | D89: Bachelor | E89: 268347.07 | F89: 48269 | G89: 69 | H89: 36586 | I89: Corporate Auto | J89: Four-Door Car | K89: 282.15121 | L89: 35282.151 | M89: =DATEDIF(L89,TODAY(),"Y") -> 30
A90: CJ15590 | B90: Oregon | C90: NA | D90: Bachelor | E90: 269518.24 | F90: 32720 | G90: 67 | H90: 0 | I90: Personal Auto | J90: Four-Door Car | K90: 321.6 | L90: 35321.6 | M90: =DATEDIF(L90,TODAY(),"Y") -> 29
A91: OI48267 | B91: California | C91: NA | D91: College | E91: 604702.52 | F91: 20396 | G91: 76 | H91: 36526 | I91: Personal Auto | J91: Four-Door Car | K91: 364.8 | L91: 35364.8 | M91: =DATEDIF(L91,TODAY(),"Y") -> 29
A92: JY67916 | B92: Oregon | C92: NA | D92: College | E92: 1317101.3 | F92: 21513 | G92: 119 | H92: 36526 | I92: Personal Auto | J92: Two-Door Car | K92: 679.82759 | L92: 35679.828 | M92: =DATEDIF(L92,TODAY(),"Y") -> 29
... A989: MB90871 | B989: Oregon | C989: F | D989: College | E989: 584741.52 | F989: 23496 | G989: 77 | H989: 0 | I989: Special Auto | J989: Four-Door Car | K989: 13.164097 | L989: 35013.164 | M989: =DATEDIF(L989,TODAY(),"Y") -> 30
A990: GT62080 | B990: Washington | C990: M | D990: High School or Below | F990: 55561 | G990: 63 | H990: 0 | I990: Personal Auto | J990: Four-Door Car | K990: 227.87207 | L990: 35227.872 | M990: =DATEDIF(L990,TODAY(),"Y") -> 30
A991: QL77686 | B991: Nevada | C991: F | D991: College | E991: 472478.61 | F991: 23986 | G991: 119 | H991: 0 | I991: Corporate Auto | J991: SUV | K991: 463.33506 | L991: 35463.335 | M991: =DATEDIF(L991,TODAY(),"Y") -> 29
A992: ON77827 | B992: Arizona | C992: F | D992: Master | E992: 279022.8 | F992: 22974 | G992: 71 | H992: 0 | I992: Personal Auto | J992: Four-Door Car | K992: 180.66797 | L992: 35180.668 | M992: =DATEDIF(L992,TODAY(),"Y") -> 30
A993: KP18988 | B993: Oregon | C993: F | D993: High School or Below | E993: 2153133.3 | F993: 0 | G993: 101 | H993: 0 | I993: Personal Auto | J993: Four-Door Car | K993: 484.8 | L993: 35484.8 | M993: =DATEDIF(L993,TODAY(),"Y") -> 29
A994: TI92884 | B994: Arizona | C994: M | D994: Bachelor | E994: 1262283.3 | F994: 61844 | G994: 106 | H994: 0 | I994: Personal Auto | J994: Sports Car | K994: 508.8 | L994: 35508.8 | M994: =DATEDIF(L994,TODAY(),"Y") -> 29
A995: JH73503 | B995: Arizona | C995: M | D995: Doctor | E995: 2017196.1 | F995: 24804 | G995: 73 | H995: 0 | I995: Personal Auto | J995: Two-Door Car | K995: 350.4 | L995: 35350.4 | M995: =DATEDIF(L995,TODAY(),"Y") -> 29
A996: YE97964 | B996: Cali | C996: F | D996: Bachelor | E996: 1646436.6 | F996: 27760 | G996: 104 | H996: 0 | I996: Personal Auto | J996: SUV | K996: 302.76428 | L996: 35302.764 | M996: =DATEDIF(L996,TODAY(),"Y") -> 30
A997: VA30351 | B997: Oregon | C997: F | D997: High School or Below | E997: 559538.99 | F997: 74454 | G997: 71 | H997: 0 | I997: Personal Auto | J997: Four-Door Car | K997: 340.8 | L997: 35340.8 | M997: =DATEDIF(L997,TODAY(),"Y") -> 29
A998: PV55726 | B998: Oregon | C998: F | D998: Master | E998: 417068.73 | F998: 29462 | G998: 107 | H998: 36526 | I998: Personal Auto | J998: SUV | K998: 513.6 | L998: 35513.6 | M998: =DATEDIF(L998,TODAY(),"Y") -> 29
A999: UC88305 | B999: Arizona | C999: F | D999: College | E999: 266544.71 | F999: 52266 | G999: 68 | H999: 0 | I999: Corporate Auto | J999: Two-Door Car | K999: 141.92284 | L999: 35141.923 | M999: =DATEDIF(L999,TODAY(),"Y") -> 30
A1000: TS53809 | B1000: Oregon | C1000: M | D1000: Bachelor | E1000: 709891.41 | F1000: 0 | G1000: 70 | H1000: 0 | I1000: Personal Auto | J1000: Two-Door Car | K1000: 349.78305 | L1000: 35349.783 | M1000: =DATEDIF(L1000,TODAY(),"Y") -> 29
...

Sheet Assurance data
A1: Customer | B1: Coverage | C1: Sales Channel | D1: Vehicle Size
A2: BU79786 | B2: Basic | C2: Agent | D2: Medsize
A3: QZ44356 | B3: Extended | C3: Agent | D3: Medsize
A4: AI49188 | B4: Premium | C4: Agent | D4: Medsize
A5: WW63253 | B5: Basic | C5: Call Center | D5: Medsize
A6: HB64268 | B6: Basic | C6: Agent | D6: Medsize
A7: OC83172 | B7: Basic | C7: Web | D7: Medsize
A8: XZ87318 | B8: Basic | C8: Agent | D8: Medsize
A9: CF85061 | B9: Premium | C9: Agent | D9: Medsize
A10: DY87989 | B10: Basic | C10: Agent | D10: Medsize
A11: BQ94931 | B11: Extended | C11: Branch | D11: Medsize
A12: SX51350 | B12: Basic | C12: Agent | D12: Small
... A9135: Y167826 | B9135: Extended | C9135: Call Center | D9135: Medsize

Sheet Hoja1
A1: Customer | B1: ST | C1: GENDER | D1: Education | E1: Customer Lifetime Value | F1: Income | G1: Monthly Premium Auto | H1: Number of Open Complaints | I1: Policy Type | J1: Vehicle Class | K1: Total Claim Amount | L1: Date | M1: Suma | N1: Promedio | O1: Contar | P1: Contar si
A2: RB50392 | B2: Washington | C2: NA | D2: Master | F2: 0 | G2: 1000 | H2: 0 | I2: Personal Auto | J2: Four-Door Car | K2: 2.704934 | L2: 35002.705 | M2: =SUM(F2:F1072) -> 42085696 | N2: =AVERAGE(G2:G1072) -> 193.23436 | O2: =COUNT(G2:G1072) -> 1071 | P2: =COUNTIF(G2:G1072,68) -> 31
A3: QZ44356 | B3: Arizona | C3: F | D3: Bachelor | E3: 697953.59 | F3: 0 | G3: 94 | H3: 0 | I3: Personal Auto | J3: Four-Door Car | K3: 1131.4649 | L3: 36131.465
A4: AI49188 | B4: Nevada | C4: F | D4: Bachelor | E4: 1288743.2 | F4: 48767 | G4: 108 | H4: 0 | I4: Personal Auto | J4: Two-Door Car | K4: 566.47225 | L4: 35566.472 | M4: Maximo | N4: Minimo | O4: si | P4: CONCAT
A5: WW63253 | B5: California | C5: M | D5: Bachelor | E5: 764586.18 | F5: 0 | G5: 106 | H5: 0 | I5: Corporate Auto | J5: SUV | K5: 529.88134 | L5: 35529.881 | M5: =MAX(G2:G1072) -> 35354 | N5: =MIN(G2:G1072) -> 61 | O5: =IF(G2>100,"POOR","RICH") -> POOR | P5: =CONCATENATE(A2," - ",B2) -> RB50392 - Washington
A6: GA49547 | B6: Washington | C6: M | D6: High School or Below | E6: 536307.65 | F6: 36357 | G6: 68 | H6: 0 | I6: Personal Auto | J6: Four-Door Car | K6: 17.269323 | L6: 35017.269 | M6: HOY | N6: AHORA | O6: REDONDEAR
A7: OC83172 | B7: Oregon | C7: F | D7: Bachelor | E7: 825629.78 | F7: 62902 | G7: 69 | H7: 0 | I7: Personal Auto | J7: Two-Door Car | K7: 159.38304 | L7: 35159.383 | M7: =TODAY() -> 46275 | N7: =NOW() -> 46275.613 | O7: =ROUND(K2,2) -> 2.7
A8: XZ87318 | B8: Oregon | C8: F | D8: College | E8: 538089.86 | F8: 55350 | G8: 67 | H8: 0 | I8: Corporate Auto | J8: Four-Door Car | K8: 321.6 | L8: 35321.6 | M8: BUSCARV
A9: CF85061 | B9: Arizona | C9: M | D9: Master | E9: 721610.03 | F9: 0 | G9: 101 | H9: 0 | I9: Corporate Auto | J9: Four-Door Car | K9: 363.02968 | L9: 35363.03 | M9: =VLOOKUP(A2,AssuranceTable,2,FALSE) -> Basic
A10: DY87989 | B10: Oregon | C10: M | D10: Bachelor | E10: 2412750.4 | F10: 14072 | G10: 71 | H10: 0 | I10: Corporate Auto | J10: Four-Door Car | K10: 511.2 | L10: 35511.2
A11: BQ94931 | B11: Oregon | C11: F | D11: College | E11: 738817.81 | F11: 28812 | G11: 93 | H11: 0 | I11: Special Auto | J11: Four-Door Car | K11: 425.52783 | L11: 35425.528
A12: SX51350 | B12: California | C12: M | D12: College | E12: 473899.2 | F12: 0 | G12: 67 | H12: 0 | I12: Personal Auto | J12: Four-Door Car | K12: 482.4 | L12: 35482.4
A13: VQ65197 | B13: California | C13: NA | D13: College | E13: 819719.71 | F13: 0 | G13: 110 | H13: 0 | I13: Personal Auto | J13: SUV | K13: 528 | L13: 35528
A14: DP39365 | B14: California | C14: NA | D14: Master | E14: 879879.7 | F14: 77026 | G14: 110 | H14: 36557 | I14: Corporate Auto | J14: Four-Door Car | K14: 472.02974 | L14: 35472.03
A15: SJ95423 | B15: Arizona | C15: NA | D15: High School or Below | E15: 881901.89 | F15: 99845 | G15: 110 | H15: 36526 | I15: Corporate Auto | J15: SUV | K15: 528 | L15: 35528
A16: IL66569 | B16: California | C16: NA | D16: College | E16: 538443.17 | F16: 83689 | G16: 70 | H16: 36557 | I16: Corporate Auto | J16: Four-Door Car | K16: 307.13913 | L16: 35307.139
A17: BW63560 | B17: Oregon | C17: NA | D17: Bachelor | E17: 746313.94 | F17: 24599 | G17: 64 | H17: 36526 | I17: Corporate Auto | J17: Four-Door Car | K17: 42.920271 | L17: 35042.92
A18: FV94802 | B18: Nevada | C18: NA | D18: High School or Below | E18: 256686.78 | F18: 25049 | G18: 67 | H18: 0 | I18: Personal Auto | J18: Two-Door Car | K18: 454.2451 | L18: 35454.245
A19: OE15005 | B19: Cali | C19: NA | D19: College | E19: 394524.16 | F19: 28855 | G19: 101 | H19: 0 | I19: Personal Auto | J19: SUV | K19: 647.44203 | L19: 35647.442
A20: WC83389 | B20: Oregon | C20: NA | D20: College | E20: 571033.31 | F20: 51148 | G20: 72 | H20: 0 | I20: Personal Auto | J20: Four-Door Car | K20: 308.98166 | L20: 35308.982
A21: FL50705 | B21: California | C21: NA | D21: High School or Below | E21: 816261.71 | F21: 66140 | G21: 101 | H21: 0 | I21: Corporate Auto | J21: Four-Door Car | K21: 484.8 | L21: 35484.8
... A79: XW13033 | B79: Nevada | C79: NA | D79: College | E79: 800947.28 | F79: 20961 | G79: 67 | H79: 0 | I79: Personal Auto | J79: Four-Door Car | K79: 321.6 | L79: 35321.6
A80: SP81997 | B80: Washington | C80: F | D80: Master | F80: 41275 | G80: 96 | H80: 0 | I80: Personal Auto | J80: Four-Door Car | K80: 41.122303 | L80: 35041.122
A81: OM82309 | B81: California | C81: NA | D81: Bachelor | E81: 5816655.3 | F81: 61321 | G81: 186 | H81: 36526 | I81: Personal Auto | J81: Luxury Car | K81: 427.63121 | L81: 35427.631
A82: ZU35962 | B82: California | C82: NA | D82: College | E82: 802522.94 | F82: 0 | G82: 77 | H82: 0 | I82: Personal Auto | J82: Two-Door Car | K82: 25.807685 | L82: 35025.808
A83: VH85817 | B83: California | C83: NA | D83: High School or Below | E83: 578018.22 | F83: 51066 | G83: 74 | H83: 0 | I83: Personal Auto | J83: Four-Door Car | K83: 787.99331 | L83: 35787.993
A84: DT85712 | B84: California | C84: NA | D84: Doctor | E84: 411853.91 | F84: 34378 | G84: 102 | H84: 0 | I84: Personal Auto | J84: SUV | K84: 489.6 | L84: 35489.6
A85: YJ88573 | B85: Nevada | C85: NA | D85: Master | E85: 252307.02 | F85: 43072 | G85: 63 | H85: 0 | I85: Personal Auto | J85: Four-Door Car | K85: 302.4 | L85: 35302.4
A86: SQ19467 | B86: Oregon | C86: NA | D86: College | E86: 655421.64 | F86: 25222 | G86: 90 | H86: 0 | I86: Personal Auto | J86: Four-Door Car | K86: 475.62325 | L86: 35475.623
A87: YB66933 | B87: Washington | C87: F | D87: Bachelor | E87: 538275.2 | F87: 77552 | G87: 68 | H87: 36526 | I87: Corporate Auto | J87: Four-Door Car | K87: 45.215059 | L87: 35045.215
A88: ET79815 | B88: California | C88: NA | D88: College | E88: 592672.94 | F88: 23091 | G88: 96 | H88: 36647 | I88: Personal Auto | J88: Four-Door Car | K88: 460.8 | L88: 35460.8
A89: QC35222 | B89: California | C89: NA | D89: Bachelor | E89: 268347.07 | F89: 48269 | G89: 69 | H89: 36586 | I89: Corporate Auto | J89: Four-Door Car | K89: 282.15121 | L89: 35282.151
A90: CJ15590 | B90: Oregon | C90: NA | D90: Bachelor | E90: 269518.24 | F90: 32720 | G90: 67 | H90: 0 | I90: Personal Auto | J90: Four-Door Car | K90: 321.6 | L90: 35321.6
A91: OI48267 | B91: California | C91: NA | D91: College | E91: 604702.52 | F91: 20396 | G91: 76 | H91: 36526 | I91: Personal Auto | J91: Four-Door Car | K91: 364.8 | L91: 35364.8
A92: JY67916 | B92: Oregon | C92: NA | D92: College | E92: 1317101.3 | F92: 21513 | G92: 119 | H92: 36526 | I92: Personal Auto | J92: Two-Door Car | K92: 679.82759 | L92: 35679.828
... A989: MB90871 | B989: Oregon | C989: F | D989: College | E989: 584741.52 | F989: 23496 | G989: 77 | H989: 0 | I989: Special Auto | J989: Four-Door Car | K989: 13.164097 | L989: 35013.164
A990: GT62080 | B990: Washington | C990: M | D990: High School or Below | F990: 55561 | G990: 63 | H990: 0 | I990: Personal Auto | J990: Four-Door Car | K990: 227.87207 | L990: 35227.872
A991: QL77686 | B991: Nevada | C991: F | D991: College | E991: 472478.61 | F991: 23986 | G991: 119 | H991: 0 | I991: Corporate Auto | J991: SUV | K991: 463.33506 | L991: 35463.335
A992: ON77827 | B992: Arizona | C992: F | D992: Master | E992: 279022.8 | F992: 22974 | G992: 71 | H992: 0 | I992: Personal Auto | J992: Four-Door Car | K992: 180.66797 | L992: 35180.668
A993: KP18988 | B993: Oregon | C993: F | D993: High School or Below | E993: 2153133.3 | F993: 0 | G993: 101 | H993: 0 | I993: Personal Auto | J993: Four-Door Car | K993: 484.8 | L993: 35484.8
...
